Workbook

Sheet Exec Summary
A1: ECHOSCAPE — Executive Budget Summary
A2: Conservative base case • US/Canada 1099 contractors • 9–12 month Steam launch • Simultaneous iOS + Android M15 • All figures live from Assumptions
A5: ='Monthly Budget'!U47 -> 271500 | B5: =Assumptions!$B$7 -> 12 | C5: =Assumptions!$B$8 -> 15 | D5: =18 -> 18 | E5: =5 -> 5 | F5: =Assumptions!$B$47/'Monthly Budget'!U47 -> 0.036832413
A6: Total Budget Ask | B6: Steam Launch Month | C6: Mobile Launch Month | D6: Months of Runway | E6: Team Size (w/ Prod.) | F6: Contingency %
A8: Budget Category | B8: Steam Dev (M1–M12) | C8: Mobile Phase (M13–M18) | D8: 18-Mo Total | E8: % of Budget | F8: Notes
A9: Staffing | B9: =SUM('Monthly Budget'!C10:N10) -> 205000 | C9: =SUM('Monthly Budget'!O10:T10) -> 0 | D9: ='Monthly Budget'!U10 -> 205000 | E9: =IF(D15=0,0,D9/D15) -> 0.75506446 | F9: Founder + 2 Engineers + Designer + Producer (optional). Set Producer to $0 on Assumptions for lean model.
A10: Legal & Admin | B10: =SUM('Monthly Budget'!C17:N17) -> 1400 | C10: =SUM('Monthly Budget'!O17:T17) -> 0 | D10: ='Monthly Budget'!U17 -> 1400 | E10: =IF(D15=0,0,D10/D15) -> 0.0051565378 | F10: LLC formation, registered agent, legal retainer, funding-close legal, monthly bookkeeping.
A11: Travel & Events | B11: =SUM('Monthly Budget'!C23:N23) -> 17400 | C11: =SUM('Monthly Budget'!O23:T23) -> 0 | D11: ='Monthly Budget'!U23 -> 17400 | E11: =IF(D15=0,0,D11/D15) -> 0.064088398 | F11: GDC (M5), Wellness conf (M6), Awesome Con DC (M7), PAX (M8). Set any to $0 to skip.
A12: Hardware & Software | B12: =SUM('Monthly Budget'!C30:N30)+SUM('Monthly Budget'!C33:N33) -> 8700 | C12: =SUM('Monthly Budget'!O30:T30)+SUM('Monthly Budget'!O33:T33) -> 0 | D12: ='Monthly Budget'!U30+'Monthly Budget'!U33 -> 8700 | E12: =IF(D15=0,0,D12/D15) -> 0.032044199 | F12: Dev hardware + test devices. Software: licenses, music library, Steam/Apple/Google fees.
A13: Marketing | B13: =SUM('Monthly Budget'!C42:N42) -> 31000 | C13: =SUM('Monthly Budget'!O42:T42) -> 3000 | D13: ='Monthly Budget'!U42 -> 34000 | E13: =IF(D15=0,0,D13/D15) -> 0.1252302 | F13: Branding (M2), pre-launch ramp M6–M11, launch spike M12, post-launch sustain, mobile launch M15.
A14: Contingency Reserve | B14: =SUM('Monthly Budget'!C45:N45) -> 5000 | C14: =SUM('Monthly Budget'!O45:T45) -> 0 | D14: ='Monthly Budget'!U45 -> 5000 | E14: =IF(D15=0,0,D14/D15) -> 0.018416206 | F14: Released at M12. ~8% of base budget. Set to $0 on Assumptions to model bare minimum.
A15: GRAND TOTAL (with Producer) | B15: =B9+B10+B11+B12+B13+B14 -> 268500 | C15: =C9+C10+C11+C12+C13+C14 -> 3000 | D15: =D9+D10+D11+D12+D13+D14 -> 271500 | E15: 100%
A17: LEAN TOTAL (set Producer to $0 on Assumptions) | D17: =D15-'Monthly Budget'!U9 -> 223500 | E17: ← live from model | F17: Lean Total = Grand Total minus Producer/PM row total ('Monthly Budget'!U9). Updates automatically when Producer rate is changed on Assumptions. Set Producer to $0 on Assumptions to make this equal Grand Total.
A19: FUNDING ASK — REVENUE OFFSET ASSUMPTIONS (edit blue cells)
A20: Scenario | B20: Steam Revenue Offset (M12–M18, assumed) | C20: Buffer % | D20: Calculated Ask | E20: Derivation Note
A21: Lean — no producer, $3K/mo founder | B21: 0 | C21: 0 | D21: =ROUND((D17-B21)*(1+C21),-3) -> 224000 | E21: Lean Total (live, Producer=$0) minus Steam revenue offset, multiplied by (1 + Buffer %). Rounded to nearest $1,000.
A22: Base Case — full team, $4K founder | B22: 0 | C22: 0 | D22: =ROUND((D15-B22)*(1+C22),-3) -> 272000 | E22: Grand Total (with Producer, live) minus offset × (1 + 0% buffer). Full cost coverage; no revenue assumed at raise date.
A23: Comfortable — full team + 25% buffer ★ RECOMMENDED | B23: 0 | C23: 0.25 | D23: =ROUND((D15-B23)*(1+C23),-3) -> 339000 | E23: Grand Total × (1 + 25% buffer) − $0 offset. Conservative — no revenue assumed; absorbs scope creep & delays. Updates automatically if costs change.
A24: Growth — elevated post-launch marketing | B24: 0 | C24: 0.43 | D24: =ROUND((D15-B24)*(1+C24),-3) -> 388000 | E24: Grand Total × (1 + 43% buffer) − $0 offset. Elevated paid UA spend M13–M18; targets 10K+ Y1 units. Adjust buffer % to tune.
A25: FUNDING SCENARIOS
A26: Scenario | B26: Ask Amount | C26: Runway | D26: Team Config | E26: Assumptions to Set
A27: Lean — no producer, $3K/mo founder | B27: =TEXT(D21,"$#,##0") -> $224,000 | C27: 12–14 mo | D27: Founder + Eng1 + Eng2 + Designer | E27: Set Producer=$0, Founder=$3,000 | F27: Derived from D21 above: Lean Total × (1+0%) − $0. Updates live when Assumptions change.
A28: Base Case — full team, $4K founder (current model) | B28: =TEXT(D22,"$#,##0") -> $272,000 | F28: Derived from D22: Grand Total × (1+0%) − $0. Full cost, no revenue assumed.
A29: Comfortable — base + 25% buffer ★ RECOMMENDED | B29: =TEXT(D23,"$#,##0") -> $339,000 | F29: Derived from D23: Grand Total × 1.25 − $0. Recommended buffer for pre-seed credibility.
A30: Growth — elevated post-launch marketing | B30: =TEXT(D24,"$#,##0") -> $388,000 | F30: Derived from D24: Grand Total × 1.43 − $0. Elevated UA; adjust C24 to tune.
A32: ★ RECOMMENDED ASK — See D23 in the offset table above (updates live). Equals Grand Total × 1.25 with no revenue offset assumed — conservative and credible for pre-seed. To model scenarios: change Buffer % in col C or add expected Steam revenue in col B.
A34: KEY DE-RISKING FACTORS (for investor narrative)
A35: ✓ Working prototype exists | B35: Technical risk materially lower than greenfield. Core concept is already validated.
A36: ✓ Simple port scope confirmed | B36: Unreal conversion = M1 only (pro-bono). Feature development starts M2 — faster than typical.
A37: ✓ Pro-bono Unreal engineering M1 | B37: Saves ~$8,500 vs. a fully paid conversion month. Signals team commitment to investors.
A38: ✓ Unreal Engine — free to $1M revenue
A39: ✓ Category white space on Steam | B39: 10 of 14 direct competitors have <200 reviews. A funded campaign leads the category immediately.
A40: ✓ Simultaneous mobile launch M15 | B40: Single consolidated marketing moment at M15. More efficient per dollar than two staggered campaigns.
A41: ✓ Awesome Con DC — local conference | B41: MD/DC-based. Lowest-cost conference on the list ($1,200 vs. $8,500 for GDC). Demonstrates budget discipline.
A42: ✓ 1099 contractor structure | B42: No payroll taxes, benefits, or HR overhead. Clean, investor-friendly structure.
A44: ECHOSCAPE : Indie (Steam) Market Analysis | Budget Model v4 | March 2026 | Confidential

Sheet Assumptions
A1: ECHOSCAPE — Model Assumptions | Edit BLUE cells only
A2: Every blue cell drives the Monthly Budget and Exec Summary automatically. Set any value to $0 to remove it from the model.
A4: A — TIMELINE
A5: Input | B5: Month # | C5: Notes
A6: Steam Early Access launch — month # | B6: 10 | C6: M10 ≈ 9–10 months; EA gives algorithm boost
A7: Steam Full Release — month # | B7: 12 | C7: M12 = 2 months after EA; align with a Steam sale
A8: Mobile launch — month # | B8: 15 | C8: Simultaneous iOS + Android; 3 months post full release
A10: B — STAFFING ($/month, 1099 contractors, US/Canada)
A11: Role | B11: $/Month | C11: Active Period & Notes
A12: Founder stipend | B12: 4000 | C12: M1–M18 all months; try $3K or $5K to see impact
A13: Engineer 1 — paid months | B13: 8500 | C13: M1 pro-bono (simple port); paid M2–M12 for features/polish
A14: Engineer 2 — mobile/QA | B14: 7500 | C14: M7–M18; joins early to build dual iOS+Android test env
A15: Designer — part-time rate | B15: 3250 | C15: M2–M4 at 50% capacity
A16: Designer — full-time rate | B16: 6500 | C16: M5–M12 full rate
A17: Producer / PM ← OPTIONAL | B17: 6000 | C17: M4–M12; set to $0 to remove role and save ~$54K
A19: C — TRAVEL & EVENTS (set to $0 to skip any event)
A20: Event | B20: Total Cost ($) | C20: Timing & Notes
A21: GDC — 2 attendees | B21: 8500 | C21: M5 — reg $1,600 + flights $800 + hotel 4 nights + meals × 2
A22: PAX East or West — 2 attendees | B22: 5500 | C22: M8 — reg $500 + flights $600 + hotel 3 nights + meals × 2
A23: Wellness conference — 1 person | B23: 2200 | C23: M6 — e.g. Mindful Life Conference; solo trip
A24: Awesome Con DC — 2 attendees | B24: 1200 | C24: M7 — local to MD; day badges + food, no hotel needed
A26: D — HARDWARE & SOFTWARE (set to $0 to exclude any item)
A27: Item | B27: Amount ($) | C27: Timing & Notes
A28: Dev hardware & test devices | B28: 3700 | C28: M1 $2,200 (MacBook + iPhone) + M7 $800 (Android) + $700 misc
A29: Software licenses — Year 1 | B29: 2400 | C29: M1 — Adobe CC, Perforce, Jira, misc SaaS tools
A30: Software licenses — Year 2 | B30: 2400 | C30: M13 — annual renewal
A31: Music library license | B31: 1200 | C31: M1 — Musicbed or Epidemic Sound; perpetual sync rights
A32: Steam developer fee | B32: 100 | C32: M1 — $100 app deposit; recouped at $1K gross revenue
A33: Apple developer account | B33: 99 | C33: M12 — register ahead of M15 simultaneous mobile launch
A34: Google Play account | B34: 25 | C34: M12 — one-time lifetime fee
A36: E — MARKETING SPEND ($/month per phase)
A37: Phase | B37: $/Month | C37: Active Months & Notes
A38: Marketing — pre-launch ramp (M6–M9) | B38: 3500 | C38: Influencer seeding, PR outreach, social test campaigns
A39: Marketing — pre-launch peak (M10–M11) | B39: 4750 | C39: Intensify influencer, press embargo coordination
A40: Marketing — launch month (M12) | B40: 4000 | C40: Launch spike: paid social surge + influencer activation
A41: Marketing — post-launch sustain (M13–M14) | B41: 1500 | C41: Community management, review cultivation
A42: Marketing — mobile launch (M15) | B42: 2500 | C42: Simultaneous iOS + Android launch campaign
A43: Marketing — post-mobile (M16–M18) | B43: 1000 | C43: Sustaining / retargeting across all platforms
A45: F — CONTINGENCY RESERVE
A46: Item | B46: Amount ($) | C46: Notes
...

Sheet Monthly Budget
A1: ECHOSCAPE — Month-by-Month Budget | All values driven by Assumptions sheet
A2: PHASE → | C2: Pre-prod | F2: Core Dev | I2: Alpha/Beta | L2: Launch | O2: Post/Mobile | R2: Mobile Live | U2: 18-Mo Total
A3: Category | B3: Line Item | C3: M1 | D3: M2 | E3: M3 | F3: M4 | G3: M5 | H3: M6 | I3: M7 | J3: M8 | K3: M9 | L3: M10 | M3: M11 | N3: M12 | O3: M13 | P3: M14 | Q3: M15 | R3: M16 | S3: M17 | T3: M18 | U3: TOTAL | V3: How 18-Mo Total Is Calculated
A4: STAFFING
A5: Staffing | B5: Founder Stipend | C5: 2000 | D5: 2000 | E5: 2000 | F5: 2000 | G5: 2000 | H5: 2000 | I5: 2000 | J5: 2000 | K5: 2000 | L5: 2000 | M5: 2000 | U5: =SUM(C5:T5) -> 22000
A6: Staffing | B6: Engineer 1 | D6: =Assumptions!$B$13 -> 8500 | E6: =Assumptions!$B$13 -> 8500 | F6: =Assumptions!$B$13 -> 8500 | G6: =Assumptions!$B$13 -> 8500 | H6: =Assumptions!$B$13 -> 8500 | I6: =Assumptions!$B$13 -> 8500 | J6: =Assumptions!$B$13 -> 8500 | K6: =Assumptions!$B$13 -> 8500 | ... M6: =Assumptions!$B$13 -> 8500 | U6: =SUM(C6:T6) -> 85000
A7: Staffing | B7: Engineer 2 (Mobile / QA) | U7: =SUM(C7:T7) -> 0
A8: Staffing | B8: Designer | D8: 5000 | E8: 5000 | F8: 5000 | G8: 5000 | H8: 5000 | I8: 5000 | J8: 5000 | K8: 5000 | L8: 5000 | M8: 5000 | U8: =SUM(C8:T8) -> 50000
A9: Staffing | B9: Producer / PM | F9: =Assumptions!$B$17 -> 6000 | G9: =Assumptions!$B$17 -> 6000 | H9: =Assumptions!$B$17 -> 6000 | I9: =Assumptions!$B$17 -> 6000 | J9: =Assumptions!$B$17 -> 6000 | K9: =Assumptions!$B$17 -> 6000 | L9: =Assumptions!$B$17 -> 6000 | M9: =Assumptions!$B$17 -> 6000 | U9: =SUM(C9:T9) -> 48000
A10: Subtotal | B10: Staffing | C10: =SUM(C5:C9) -> 2000 | D10: =SUM(D5:D9) -> 15500 | E10: =SUM(E5:E9) -> 15500 | F10: =SUM(F5:F9) -> 21500 | G10: =SUM(G5:G9) -> 21500 | H10: =SUM(H5:H9) -> 21500 | I10: =SUM(I5:I9) -> 21500 | J10: =SUM(J5:J9) -> 21500 | ... T10: =SUM(T5:T9) -> 0 | U10: =SUM(C10:T10) -> 205000 | V10: Staffing Subtotal — SUM of all 5 role rows across M1–M18. Founder $4K × 18 mo = $72K. Eng1 $8.5K × 11 mo (M2–M12; M1 pro-bono=$0) = $93.5K. Eng2 $7.5K × 12 mo (M7–M18) = $90K. Designer $3.25K × 3 mo (M2–M4 PT) + $6.5K × 8 mo (M5–M12 FT) = $61.75K. Producer $6K × 9 mo (M4–M12) = $54K. Total = $371.25K. Set Producer=$0 on Assumptions to reduce by $54K.
A11: LEGAL & ADMIN
A12: Legal | B12: LLC Formation (Delaware) | C12: =Assumptions!$B$51 -> 750 | U12: =SUM(C12:T12) -> 750
A13: Legal | B13: Registered Agent Fee | C13: =Assumptions!$B$52 -> 150 | U13: =SUM(C13:T13) -> 150
A14: Legal | B14: Legal Retainer (M1–M6, $500/mo) | C14: =Assumptions!$B$54/6 -> 500 | U14: =SUM(C14:T14) -> 500
A15: Legal | B15: Legal — Funding Close | U15: =SUM(C15:T15) -> 0
A16: Legal | B16: Accounting / Bookkeeping | U16: =SUM(C16:T16) -> 0
A17: Subtotal | B17: Legal & Admin | C17: =SUM(C12:C16) -> 1400 | D17: =SUM(D12:D16) -> 0 | E17: =SUM(E12:E16) -> 0 | F17: =SUM(F12:F16) -> 0 | G17: =SUM(G12:G16) -> 0 | H17: =SUM(H12:H16) -> 0 | I17: =SUM(I12:I16) -> 0 | J17: =SUM(J12:J16) -> 0 | ... U17: =SUM(U12:U16) -> 1400 | V17: Legal & Admin Subtotal — LLC formation $750 + registered agent $150 (M1 one-time). Legal retainer $500/mo × 6 mo (M1–M6) = $3K. Funding-close legal $3,500 (M6 one-time). Bookkeeping $300/mo × 18 mo = $5.4K. Total = $12.95K.
A18: TRAVEL & EVENTS
A19: Events | B19: GDC — San Francisco (2 people, M5) | G19: =Assumptions!$B$21 -> 8500 | U19: =SUM(C19:T19) -> 8500
A20: Events | B20: PAX East or West (2 people, M8) | J20: =Assumptions!$B$22 -> 5500 | U20: =SUM(C20:T20) -> 5500
A21: Events | B21: Wellness Conference (1 person, M6) | H21: =Assumptions!$B$23 -> 2200 | U21: =SUM(C21:T21) -> 2200
A22: Events | B22: Awesome Con DC (2 people, M7) | I22: =Assumptions!$B$24 -> 1200 | U22: =SUM(C22:T22) -> 1200
A23: Subtotal | B23: Travel & Events | C23: =SUM(C19:C22) -> 0 | D23: =SUM(D19:D22) -> 0 | E23: =SUM(E19:E22) -> 0 | F23: =SUM(F19:F22) -> 0 | G23: =SUM(G19:G22) -> 8500 | H23: =SUM(H19:H22) -> 2200 | I23: =SUM(I19:I22) -> 1200 | J23: =SUM(J19:J22) -> 5500 | ... T23: =SUM(T19:T22) -> 0 | U23: =SUM(C23:T23) -> 17400 | V23: Travel & Events Subtotal — GDC M5 $8,500 + Wellness conf M6 $2,200 + Awesome Con DC M7 $1,200 + PAX M8 $5,500. Total = $17.4K. All values pulled from Assumptions. Set any event to $0 to exclude.
A24: SOFTWARE & TOOLS
A25: Software | B25: Software Licenses (annual renewal) | C25: =Assumptions!$B$29 -> 2400 | U25: =SUM(C25:T25) -> 2400
A26: Software | B26: Music Library License | C26: =Assumptions!$B$31 -> 1200 | U26: =SUM(C26:T26) -> 1200
A27: Software | B27: Steam Developer Fee | C27: =Assumptions!$B$32 -> 100 | U27: =SUM(C27:T27) -> 100
A28: Software | B28: Apple Developer Account | U28: =SUM(C28:T28) -> 0
A29: Software | B29: Google Play Account | U29: =SUM(C29:T29) -> 0
A30: Subtotal | B30: Software & Tools | C30: =SUM(C25:C29) -> 3700 | D30: =SUM(D25:D29) -> 0 | E30: =SUM(E25:E29) -> 0 | F30: =SUM(F25:F29) -> 0 | G30: =SUM(G25:G29) -> 0 | H30: =SUM(H25:H29) -> 0 | I30: =SUM(I25:I29) -> 0 | J30: =SUM(J25:J29) -> 0 | ... U30: =SUM(U25:U29) -> 3700 | V30: Software & Tools Subtotal — Annual licenses $2,400 (M1) + $2,400 renewal (M13). Music library $1,200 (M1). Steam fee $100 (M1). Apple dev $99 (M12). Google Play $25 (M12). Total = $6,224. All from Assumptions.
A31: HARDWARE & TEST DEVICES
A32: Hardware | B32: Dev Hardware & Test Devices (see Assumptions for breakdown) | C32: 5000 | U32: =SUM(C32:T32) -> 5000
A33: Subtotal | B33: Hardware | C33: =SUM(C32) -> 5000 | D33: =SUM(D32) -> 0 | E33: =SUM(E32) -> 0 | F33: =SUM(F32) -> 0 | G33: =SUM(G32) -> 0 | H33: =SUM(H32) -> 0 | I33: =SUM(I32) -> 0 | J33: =SUM(J32) -> 0 | ... T33: =SUM(T32) -> 0 | U33: =SUM(C33:T33) -> 5000 | V33: Hardware Subtotal — MacBook + iPhone $2,200 (M1); Android test device $800 (M7); misc hardware $700 spread M1–M3 proportionally per Assumptions. Total = $3,700.
A34: MARKETING & BRANDING
A35: Marketing | B35: Branding / Identity Design (M2, one-time) | D35: =Assumptions!$B$56 -> 3500 | U35: =SUM(C35:T35) -> 3500
A36: Marketing | B36: Pre-launch — ramp (M6–M9) | H36: =Assumptions!$B$38 -> 3500 | I36: =Assumptions!$B$38 -> 3500 | J36: =Assumptions!$B$38 -> 3500 | K36: =Assumptions!$B$38 -> 3500 | U36: =SUM(C36:T36) -> 14000
A37: Marketing | B37: Pre-launch — peak (M10–M11) | L37: =Assumptions!$B$39 -> 4750 | M37: =Assumptions!$B$39 -> 4750 | U37: =SUM(C37:T37) -> 9500
A38: Marketing | B38: Launch month spend (M12) | N38: =Assumptions!$B$40 -> 4000 | U38: =SUM(C38:T38) -> 4000
A39: Marketing | B39: Post-launch sustain (M13–M14) | O39: =Assumptions!$B$41 -> 1500 | P39: =Assumptions!$B$41 -> 1500 | U39: =SUM(C39:T39) -> 3000
A40: Marketing | B40: Mobile launch campaign (M15) | U40: =SUM(C40:T40) -> 0
...

Sheet Summary & Ask
A1: ECHOSCAPE — Funding Summary & Investor Ask
A2: All totals pull live from Monthly Budget | Conservative base case | US/Canada 1099 contractors | 9–12 month Steam launch
A4: BUDGET BY CATEGORY (live from Monthly Budget sheet)
A5: Category | B5: Steam Phase M1–M12 | C5: Mobile Phase M13–M18 | D5: 18-Mo Total | E5: % of Total
A6: Staffing (all roles) | B6: =SUM('Monthly Budget'!C5:N5)+SUM('Monthly Budget'!C6:N6)+SUM('Monthly Budget'!C7:N7)+SUM('Monthly Budget'!C8:N8)+SUM('Monthly Budget'!C9:N9) -> 205000 | C6: =SUM('Monthly Budget'!O5:T5)+SUM('Monthly Budget'!O6:T6)+SUM('Monthly Budget'!O7:T7)+SUM('Monthly Budget'!O8:T8)+SUM('Monthly Budget'!O9:T9) -> 0 | D6: =B6+C6 -> 205000 | E6: =IF(D13=0,0,D6/D13) -> 0.75506446
A7: Legal & Admin | B7: =SUM('Monthly Budget'!C12:N12)+SUM('Monthly Budget'!C13:N13)+SUM('Monthly Budget'!C14:N14)+SUM('Monthly Budget'!C15:N15)+SUM('Monthly Budget'!C16:N16) -> 1400 | C7: =SUM('Monthly Budget'!O12:T12)+SUM('Monthly Budget'!O13:T13)+SUM('Monthly Budget'!O14:T14)+SUM('Monthly Budget'!O15:T15)+SUM('Monthly Budget'!O16:T16) -> 0 | D7: =B7+C7 -> 1400 | E7: =IF(D13=0,0,D7/D13) -> 0.0051565378
A8: Travel & Events | B8: =SUM('Monthly Budget'!C19:N19)+SUM('Monthly Budget'!C20:N20)+SUM('Monthly Budget'!C21:N21)+SUM('Monthly Budget'!C22:N22) -> 17400 | C8: =SUM('Monthly Budget'!O19:T19)+SUM('Monthly Budget'!O20:T20)+SUM('Monthly Budget'!O21:T21)+SUM('Monthly Budget'!O22:T22) -> 0 | D8: =B8+C8 -> 17400 | E8: =IF(D13=0,0,D8/D13) -> 0.064088398
A9: Software & Tools | B9: =SUM('Monthly Budget'!C25:N25)+SUM('Monthly Budget'!C26:N26)+SUM('Monthly Budget'!C27:N27)+SUM('Monthly Budget'!C28:N28)+SUM('Monthly Budget'!C29:N29) -> 3700 | C9: =SUM('Monthly Budget'!O25:T25)+SUM('Monthly Budget'!O26:T26)+SUM('Monthly Budget'!O27:T27)+SUM('Monthly Budget'!O28:T28)+SUM('Monthly Budget'!O29:T29) -> 0 | D9: =B9+C9 -> 3700 | E9: =IF(D13=0,0,D9/D13) -> 0.013627993
A10: Hardware & Test Devices | B10: =SUM('Monthly Budget'!C32:N32) -> 5000 | C10: =SUM('Monthly Budget'!O32:T32) -> 0 | D10: =B10+C10 -> 5000 | E10: =IF(D13=0,0,D10/D13) -> 0.018416206
A11: Marketing & Branding | B11: =SUM('Monthly Budget'!C35:N35)+SUM('Monthly Budget'!C36:N36)+SUM('Monthly Budget'!C37:N37)+SUM('Monthly Budget'!C38:N38)+SUM('Monthly Budget'!C39:N39)+SUM('Monthly Budget'!C40:N40)+SUM('Monthly Budget'!C41:N41) -> 31000 | C11: =SUM('Monthly Budget'!O35:T35)+SUM('Monthly Budget'!O36:T36)+SUM('Monthly Budget'!O37:T37)+SUM('Monthly Budget'!O38:T38)+SUM('Monthly Budget'!O39:T39)+SUM('Monthly Budget'!O40:T40)+SUM('Monthly Budget'!O41:T41) -> 3000 | D11: =B11+C11 -> 34000 | E11: =IF(D13=0,0,D11/D13) -> 0.1252302
A12: Contingency Reserve | B12: =SUM('Monthly Budget'!C44:N44) -> 5000 | C12: =SUM('Monthly Budget'!O44:T44) -> 0 | D12: =B12+C12 -> 5000 | E12: =IF(D13=0,0,D12/D13) -> 0.018416206
A13: GRAND TOTAL (with Producer) | B13: =B6+B7+B8+B9+B10+B11+B12 -> 268500 | C13: =C6+C7+C8+C9+C10+C11+C12 -> 3000 | D13: =B13+C13 -> 271500
A15: LEAN TOTAL (set Producer to $0 on Assumptions) | B15: ← change Assumptions!B (Producer) to $0 | D15: =D13-'Monthly Budget'!U9 -> 223500 | E15: Lean Total = Grand Total minus Producer row ('Monthly Budget'!U9). Set Producer=$0 on Assumptions to make this equal Grand Total.
A17: FUNDING ASK — REVENUE OFFSET ASSUMPTIONS (edit blue cells)
A18: Scenario | B18: Steam Revenue Offset (M12–M18, assumed) | C18: Buffer % | D18: Calculated Ask | E18: Derivation Note
A19: Lean | B19: 0 | C19: 0 | D19: =ROUND((D15-B19)*(1+C19),-3) -> 224000 | E19: Lean Total (Producer=$0, live) minus offset × (1+buffer). Rounded to $1K.
A20: Base Case — full team, $4K founder | B20: 0 | C20: 0 | D20: =ROUND((D13-B20)*(1+C20),-3) -> 272000 | E20: Grand Total (with Producer, live) minus offset × (1+buffer). Rounded to $1K.
A21: Comfortable — full team + 25% buffer ★ RECOMMENDED | B21: 0 | C21: 0.25 | D21: =ROUND((D13-B21)*(1+C21),-3) -> 339000 | E21: Grand Total × (1+25%) − $0 offset. No revenue assumed — conservative investor ask. Updates live.
A22: Growth — elevated post-launch marketing | B22: 0 | C22: 0.43 | D22: =ROUND((D13-B22)*(1+C22),-3) -> 388000 | E22: Grand Total × (1+43%) − $0 offset. Elevated UA budget M13–M18. Adjust C22 to tune.
A23: FUNDING SCENARIOS — update Assumptions to match each scenario
A24: Scenario | B24: Ask | C24: Runway | D24: Team Config | E24: Key Assumptions
A25: Lean — no producer, $3K/mo founder | B25: =TEXT(D19,"$#,##0") -> $224,000 | C25: 12–14 mo | D25: Founder + Eng1 + Eng2 + Designer | E25: Set Producer=$0, Founder=$3,000 on Assumptions. Steam-first; mobile from revenue. | F25: Lean Total × (1+0%) − $0. Updates when Assumptions change.
A26: Base Case — full team, $4K founder | B26: =TEXT(D20,"$#,##0") -> $272,000 | F26: Grand Total × (1+0%) − $0. Full cost; no revenue assumed at raise date.
A27: Comfortable — base + 25% buffer ★ RECOMMENDED | B27: =TEXT(D21,"$#,##0") -> $339,000 | F27: Grand Total × 1.25 − $0. 25% buffer for scope/delay risk. Recommended pre-seed ask.
A28: Growth — + post-launch paid UA | B28: =TEXT(D22,"$#,##0") -> $388,000 | F28: Grand Total × 1.43 − $0. Elevated post-launch UA. Adjust Growth buffer % to tune.
A30: ★ RECOMMENDED ASK — See D21 in offset table above (updates live). Equals Grand Total × 1.25 with no revenue offset — conservative for pre-seed. Adjust Buffer % (C21) or add a Steam revenue offset (B21) to model scenarios.
A32: DE-RISKING FACTORS FOR INVESTOR PITCH
A33: ✓ Working prototype exists | B33: Technical risk significantly lower than greenfield. Concept is validated.
A34: ✓ Simple port scope confirmed | B34: Unreal conversion = M1 only (pro-bono). Feature dev starts M2. Faster than typical.
A35: ✓ Pro-bono Unreal engineering | B35: Saves ~$8,500 vs. a paid conversion month. Signals team commitment to investors.
A36: ✓ Unreal Engine — free to $1M
A37: ✓ Category white space on Steam | B37: 10 of 14 direct competitors have <200 reviews. Funded campaign leads the category.
A38: ✓ Simultaneous mobile launch | B38: Single consolidated campaign at M15 vs. two staggered = more efficient per dollar.
A39: ✓ 1099 contractor structure | B39: No payroll taxes, benefits, HR overhead. Clean, investor-friendly structure.
A40: ✓ Awesome Con — local conference | B40: MD/DC-based. Lowest-cost conference on the list. Demonstrates budget discipline.
A42: ECHOSCAPE : Indie (Steam) Market Analysis | Budget Model v3 (driver-based) | March 2026 | Confidential

Sheet Steam Assumptions
A1: ECHOSCAPE — Steam-Only Model Assumptions | Edit BLUE cells only
A2: Steam launch only (M1–M12). Mobile phase excluded. All values drive the Steam Monthly Budget automatically. Set any item to $0 to remove it.
A4: A — TIMELINE
A5: Input | B5: Month # | C5: Notes
A6: Steam Early Access launch — month # | B6: 10 | C6: M10 ≈ 9–10 months; EA gives algorithm boost
A7: Steam Full Release — month # | B7: 12 | C7: M12 = 2 months after EA; align with a Steam sale
A9: B — STAFFING ($/month, 1099 contractors, US/Canada)
A10: Role | B10: $/Month | C10: Active Period & Notes
A11: Founder stipend | B11: 4000 | C11: M1–M12 all months. Try $3K for lean or $5K for comfortable.
A12: Engineer 1 — paid months | B12: 8500 | C12: M1 pro-bono (Unreal port); paid M2–M12 for features/polish.
A13: Engineer 2 — QA only ← OPTIONAL | B13: 0 | C13: Set to $0 to exclude entirely. If included, covers QA M7–M12 only (no mobile build). Consider part-time rate.
A14: Designer — part-time rate | B14: 3250 | C14: M2–M4 at 50% capacity.
A15: Designer — full-time rate | B15: 6500 | C15: M5–M12 full rate.
A16: Producer / PM ← OPTIONAL | B16: 6000 | C16: M4–M12. Set to $0 to remove role and save ~$54K.
A18: C — TRAVEL & EVENTS (set to $0 to skip any event)
A19: Event | B19: Total Cost ($) | C19: Timing & Notes
A20: GDC — 2 attendees | B20: 8500 | C20: M5 — reg $1,600 + flights $800 + hotel 4 nights + meals × 2
A21: PAX East or West — 2 attendees | B21: 5500 | C21: M8 — reg $500 + flights $600 + hotel 3 nights + meals × 2
A22: Wellness conference — 1 person | B22: 2200 | C22: M6 — e.g. Mindful Life Conference; solo trip
A23: Awesome Con DC — 2 attendees | B23: 1200 | C23: M7 — local to MD; day badges + food, no hotel needed
A25: D — HARDWARE & SOFTWARE (set to $0 to exclude any item)
A26: Item | B26: Amount ($) | C26: Timing & Notes
A27: Dev hardware & test devices | B27: 2900 | C27: M1 $2,200 (MacBook + iPhone) + $700 misc. Android device excluded (mobile not in scope).
A28: Software licenses — Year 1 | B28: 2400 | C28: M1 — Adobe CC, Perforce, Jira, misc SaaS tools
A29: Music library license | B29: 1200 | C29: M1 — Musicbed or Epidemic Sound; perpetual sync rights
A30: Steam developer fee | B30: 100 | C30: M1 — $100 app deposit; recouped at $1K gross revenue
A32: E — MARKETING SPEND ($/month per phase)
A33: Phase | B33: $/Month | C33: Active Months & Notes
A34: Branding / identity design (M2, one-time) | B34: 3500 | C34: M2 — logo, style guide, Steam capsule art, trailer titles
A35: Marketing — pre-launch ramp (M6–M9) | B35: 3500 | C35: Influencer seeding, PR outreach, social test campaigns
A36: Marketing — pre-launch peak (M10–M11) | B36: 4750 | C36: Intensify influencer, press embargo coordination
A37: Marketing — launch month (M12) | B37: 4000 | C37: Launch spike: paid social surge + influencer activation
A38: Marketing — post-launch sustain (M13+) | B38: 0 | C38: Post-Steam sustain excluded from this model. Set > $0 only if continuing past M12.
A40: F — LEGAL & ADMIN
A41: Item | B41: Amount ($) | C41: Timing & Notes
A42: LLC formation (Delaware) | B42: 750 | C42: M1 — state filing + registered agent setup; one-time
A43: Registered agent — Year 1 | B43: 150 | C43: M1 — annual fee
A44: Legal retainer × 6 months | B44: 3000 | C44: M1–M6 total ($500/mo); IP review, contractor agreements, EULA
A45: Legal — funding close | B45: 3500 | C45: M6 — term sheet review, operating agreement, investor docs
A46: Accounting / bookkeeping | B46: 300 | C46: M1–M12 monthly ($300/mo); QuickBooks + 2 hrs CPA
...

Sheet Steam Monthly Budget
A1: ECHOSCAPE — Steam-Only Month-by-Month Budget | All values driven by Steam Assumptions sheet
A2: PHASE → | C2: Pre-prod | D2: Core Dev | G2: Alpha / Beta | J2: Launch Prep | L2: Launch
A3: Category | B3: Line Item | C3: M1 | D3: M2 | E3: M3 | F3: M4 | G3: M5 | H3: M6 | I3: M7 | J3: M8 | K3: M9 | L3: M10 | M3: M11 | N3: M12 | O3: TOTAL | P3: How Total Is Calculated
A4: STAFFING
A5: Staffing | B5: Founder Stipend | C5: ='Steam Assumptions'!$B$11 -> 4000 | D5: ='Steam Assumptions'!$B$11 -> 4000 | E5: ='Steam Assumptions'!$B$11 -> 4000 | F5: ='Steam Assumptions'!$B$11 -> 4000 | G5: ='Steam Assumptions'!$B$11 -> 4000 | H5: ='Steam Assumptions'!$B$11 -> 4000 | I5: ='Steam Assumptions'!$B$11 -> 4000 | J5: ='Steam Assumptions'!$B$11 -> 4000 | ... N5: ='Steam Assumptions'!$B$11 -> 4000 | O5: =SUM(C5:N5) -> 48000 | P5: Founder stipend all 12 months. Rate from Steam Assumptions B11.
A6: Staffing | B6: Engineer 1 (Unreal / Core) — M1 pro-bono | D6: ='Steam Assumptions'!$B$12 -> 8500 | E6: ='Steam Assumptions'!$B$12 -> 8500 | F6: ='Steam Assumptions'!$B$12 -> 8500 | G6: ='Steam Assumptions'!$B$12 -> 8500 | H6: ='Steam Assumptions'!$B$12 -> 8500 | I6: ='Steam Assumptions'!$B$12 -> 8500 | J6: ='Steam Assumptions'!$B$12 -> 8500 | K6: ='Steam Assumptions'!$B$12 -> 8500 | ... N6: ='Steam Assumptions'!$B$12 -> 8500 | O6: =SUM(C6:N6) -> 93500 | P6: M1 = $0 (pro-bono Unreal port). Paid M2–M12 at rate from B12.
A7: Staffing | B7: Engineer 2 (QA only, M7–M12) ← OPTIONAL — set B13=$0 to remove | I7: ='Steam Assumptions'!$B$13 -> 0 | J7: ='Steam Assumptions'!$B$13 -> 0 | K7: ='Steam Assumptions'!$B$13 -> 0 | L7: ='Steam Assumptions'!$B$13 -> 0 | M7: ='Steam Assumptions'!$B$13 -> 0 | N7: ='Steam Assumptions'!$B$13 -> 0 | O7: =SUM(C7:N7) -> 0 | P7: If included: QA/testing M7–M12 only. No mobile build. Set B13=$0 on Steam Assumptions to exclude entirely.
A8: Staffing | B8: Designer (UI/UX + Art) — PT M2–M4, FT M5–M12 | D8: ='Steam Assumptions'!$B$14 -> 3250 | E8: ='Steam Assumptions'!$B$14 -> 3250 | F8: ='Steam Assumptions'!$B$14 -> 3250 | G8: ='Steam Assumptions'!$B$15 -> 6500 | H8: ='Steam Assumptions'!$B$15 -> 6500 | I8: ='Steam Assumptions'!$B$15 -> 6500 | J8: ='Steam Assumptions'!$B$15 -> 6500 | K8: ='Steam Assumptions'!$B$15 -> 6500 | L8: ='Steam Assumptions'!$B$15 -> 6500 | M8: ='Steam Assumptions'!$B$15 -> 6500 | N8: ='Steam Assumptions'!$B$15 -> 6500 | O8: =SUM(C8:N8) -> 61750 | P8: Part-time (B14) M2–M4; full-time (B15) M5–M12.
A9: Staffing | B9: Producer / PM ← SET TO $0 ON STEAM ASSUMPTIONS TO REMOVE | F9: ='Steam Assumptions'!$B$16 -> 6000 | G9: ='Steam Assumptions'!$B$16 -> 6000 | H9: ='Steam Assumptions'!$B$16 -> 6000 | I9: ='Steam Assumptions'!$B$16 -> 6000 | J9: ='Steam Assumptions'!$B$16 -> 6000 | K9: ='Steam Assumptions'!$B$16 -> 6000 | L9: ='Steam Assumptions'!$B$16 -> 6000 | M9: ='Steam Assumptions'!$B$16 -> 6000 | N9: ='Steam Assumptions'!$B$16 -> 6000 | O9: =SUM(C9:N9) -> 54000 | P9: M4–M12. Set B16=$0 to exclude role (~$54K savings).
A10: Subtotal | B10: Staffing | C10: =C5+C6+C7+C8+C9 -> 4000 | D10: =D5+D6+D7+D8+D9 -> 15750 | E10: =E5+E6+E7+E8+E9 -> 15750 | F10: =F5+F6+F7+F8+F9 -> 21750 | G10: =G5+G6+G7+G8+G9 -> 25000 | H10: =H5+H6+H7+H8+H9 -> 25000 | I10: =I5+I6+I7+I8+I9 -> 25000 | J10: =J5+J6+J7+J8+J9 -> 25000 | ... O10: =O5+O6+O7+O8+O9 -> 257250 | P10: SUM of all staffing rows M1–M12. Founder $4K×12=$48K; Eng1 $8.5K×11=$93.5K (M1 pro-bono); Eng2 optional ($0 default); Designer PT+FT=$61.75K; Producer $6K×9=$54K optional. Totals update when Steam Assumptions change.
A11: LEGAL & ADMIN
A12: Legal | B12: LLC Formation (Delaware) | C12: ='Steam Assumptions'!$B$42 -> 750 | O12: =SUM(C12:N12) -> 750 | P12: M1 one-time. From B42.
A13: Legal | B13: Registered Agent Fee | C13: ='Steam Assumptions'!$B$43 -> 150 | O13: =SUM(C13:N13) -> 150 | P13: M1 one-time annual fee. From B43.
A14: Legal | B14: Legal Retainer (M1–M6, $500/mo) | C14: ='Steam Assumptions'!$B$44/6 -> 500 | D14: ='Steam Assumptions'!$B$44/6 -> 500 | E14: ='Steam Assumptions'!$B$44/6 -> 500 | F14: ='Steam Assumptions'!$B$44/6 -> 500 | G14: ='Steam Assumptions'!$B$44/6 -> 500 | H14: ='Steam Assumptions'!$B$44/6 -> 500 | O14: =SUM(C14:N14) -> 3000 | P14: Retainer total from B44 divided by 6 months.
A15: Legal | B15: Legal — Funding Close | H15: ='Steam Assumptions'!$B$45 -> 3500 | O15: =SUM(C15:N15) -> 3500 | P15: M6 one-time. From B45.
A16: Legal | B16: Accounting / Bookkeeping | C16: ='Steam Assumptions'!$B$46 -> 300 | D16: ='Steam Assumptions'!$B$46 -> 300 | E16: ='Steam Assumptions'!$B$46 -> 300 | F16: ='Steam Assumptions'!$B$46 -> 300 | G16: ='Steam Assumptions'!$B$46 -> 300 | H16: ='Steam Assumptions'!$B$46 -> 300 | I16: ='Steam Assumptions'!$B$46 -> 300 | J16: ='Steam Assumptions'!$B$46 -> 300 | ... N16: ='Steam Assumptions'!$B$46 -> 300 | O16: =SUM(C16:N16) -> 3600 | P16: Monthly M1–M12. From B46.
A17: Subtotal | B17: Legal & Admin | C17: =C12+C13+C14+C15+C16 -> 1700 | D17: =D12+D13+D14+D15+D16 -> 800 | E17: =E12+E13+E14+E15+E16 -> 800 | F17: =F12+F13+F14+F15+F16 -> 800 | G17: =G12+G13+G14+G15+G16 -> 800 | H17: =H12+H13+H14+H15+H16 -> 4300 | I17: =I12+I13+I14+I15+I16 -> 300 | J17: =J12+J13+J14+J15+J16 -> 300 | ... O17: =O12+O13+O14+O15+O16 -> 11000 | P17: LLC $750 + registered agent $150 (M1 one-time); retainer $500/mo M1–M6; funding close $3,500 (M6); bookkeeping $300/mo M1–M12. Total = $10,600.
A18: TRAVEL & EVENTS
A19: Events | B19: GDC — San Francisco (2 people, M5) | G19: ='Steam Assumptions'!$B$20 -> 8500 | O19: =SUM(C19:N19) -> 8500 | P19: M5. Rate from B20. Set to $0 to skip.
A20: Events | B20: PAX East or West (2 people, M8) | J20: ='Steam Assumptions'!$B$21 -> 5500 | O20: =SUM(C20:N20) -> 5500 | P20: M8. Rate from B21. Set to $0 to skip.
A21: Events | B21: Wellness Conference (1 person, M6) | H21: ='Steam Assumptions'!$B$22 -> 2200 | O21: =SUM(C21:N21) -> 2200 | P21: M6. Rate from B22. Set to $0 to skip.
A22: Events | B22: Awesome Con DC (2 people, M7) | I22: ='Steam Assumptions'!$B$23 -> 1200 | O22: =SUM(C22:N22) -> 1200 | P22: M7. Local; no hotel. Rate from B23.
A23: Subtotal | B23: Travel & Events | C23: =C19+C20+C21+C22 -> 0 | D23: =D19+D20+D21+D22 -> 0 | E23: =E19+E20+E21+E22 -> 0 | F23: =F19+F20+F21+F22 -> 0 | G23: =G19+G20+G21+G22 -> 8500 | H23: =H19+H20+H21+H22 -> 2200 | I23: =I19+I20+I21+I22 -> 1200 | J23: =J19+J20+J21+J22 -> 5500 | ... O23: =O19+O20+O21+O22 -> 17400 | P23: GDC M5 $8,500 + Wellness M6 $2,200 + Awesome Con M7 $1,200 + PAX M8 $5,500 = $17,400. All from Steam Assumptions. Zero any event to exclude.
A24: SOFTWARE & TOOLS
A25: Software | B25: Software Licenses (Year 1) | C25: ='Steam Assumptions'!$B$28 -> 2400 | O25: =SUM(C25:N25) -> 2400 | P25: M1 annual SaaS bundle. From B28.
A26: Software | B26: Music Library License | C26: ='Steam Assumptions'!$B$29 -> 1200 | O26: =SUM(C26:N26) -> 1200 | P26: M1 one-time. From B29.
A27: Software | B27: Steam Developer Fee | C27: ='Steam Assumptions'!$B$30 -> 100 | O27: =SUM(C27:N27) -> 100 | P27: M1 $100 deposit, recouped at $1K gross. From B30.
A28: Subtotal | B28: Software & Tools | C28: =C25+C26+C27 -> 3700 | D28: =D25+D26+D27 -> 0 | E28: =E25+E26+E27 -> 0 | F28: =F25+F26+F27 -> 0 | G28: =G25+G26+G27 -> 0 | H28: =H25+H26+H27 -> 0 | I28: =I25+I26+I27 -> 0 | J28: =J25+J26+J27 -> 0 | ... O28: =O25+O26+O27 -> 3700 | P28: Year 1 licenses $2,400 + music library $1,200 + Steam fee $100 = $3,700. No Year 2 renewal (model ends at M12). No Apple/Google accounts (mobile excluded).
A29: HARDWARE & TEST DEVICES
A30: Hardware | B30: Dev Hardware & Test Devices | C30: ='Steam Assumptions'!$B$27*0.759 -> 2201.1 | D30: ='Steam Assumptions'!$B$27*0.138 -> 400.2 | E30: ='Steam Assumptions'!$B$27*0.103 -> 298.7 | O30: =SUM(C30:N30) -> 2900 | P30: M1 MacBook+iPhone; M2–M3 misc. Android device excluded (mobile not in scope). From B27.
A31: Subtotal | B31: Hardware | C31: =C30 -> 2201.1 | D31: =D30 -> 400.2 | E31: =E30 -> 298.7 | F31: =F30 | G31: =G30 | H31: =H30 | I31: =I30 | J31: =J30 | ... O31: =O30 -> 2900 | P31: Hardware $2,900 total: MacBook+iPhone $2,200 (M1), misc $700 spread M1–M3. Android test device removed vs full model (~$800 savings).
A32: MARKETING & BRANDING
A33: Marketing | B33: Branding / Identity Design (M2, one-time) | D33: ='Steam Assumptions'!$B$34 -> 3500 | O33: =SUM(C33:N33) -> 3500 | P33: M2 one-time. From B34.
A34: Marketing | B34: Pre-launch — ramp (M6–M9) | H34: ='Steam Assumptions'!$B$35 -> 3500 | I34: ='Steam Assumptions'!$B$35 -> 3500 | J34: ='Steam Assumptions'!$B$35 -> 3500 | K34: ='Steam Assumptions'!$B$35 -> 3500 | O34: =SUM(C34:N34) -> 14000 | P34: M6–M9 ramp. From B35.
A35: Marketing | B35: Pre-launch — peak (M10–M11) | L35: ='Steam Assumptions'!$B$36 -> 4750 | M35: ='Steam Assumptions'!$B$36 -> 4750 | O35: =SUM(C35:N35) -> 9500 | P35: M10–M11 peak. From B36.
A36: Marketing | B36: Launch month spend (M12) | N36: ='Steam Assumptions'!$B$37 -> 4000 | O36: =SUM(C36:N36) -> 4000 | P36: M12 launch spike. From B37.
A37: Subtotal | B37: Marketing & Branding | C37: =C33+C34+C35+C36 -> 0 | D37: =D33+D34+D35+D36 -> 3500 | E37: =E33+E34+E35+E36 -> 0 | F37: =F33+F34+F35+F36 -> 0 | G37: =G33+G34+G35+G36 -> 0 | H37: =H33+H34+H35+H36 -> 3500 | I37: =I33+I34+I35+I36 -> 3500 | J37: =J33+J34+J35+J36 -> 3500 | ... O37: =O33+O34+O35+O36 -> 31000 | P37: Branding $3,500 (M2); ramp $3,500/mo × 4 mo (M6–M9) = $14K; peak $4,750/mo × 2 mo (M10–M11) = $9.5K; launch $4,000 (M12). No post-launch or mobile marketing. Total = $31,000.
A38: CONTINGENCY RESERVE
A39: Contingency | B39: Contingency Reserve (released at M12) | N39: ='Steam Assumptions'!$B$50 -> 10000 | O39: =SUM(C39:N39) -> 10000 | P39: M12 release. Set B50=$0 for bare-minimum scenario. From B50.
A40: Subtotal | B40: Contingency | C40: =C39 | D40: =D39 | E40: =E39 | F40: =F39 | G40: =G39 | H40: =H39 | I40: =I39 | J40: =J39 | ... O40: =O39 -> 10000 | P40: Lump sum at M12 (Steam full release). Default $10,000. Set to $0 on Steam Assumptions for bare-minimum model.
...

Sheet Steam Funding Scenarios
A1: ECHOSCAPE — Steam-Only Funding Scenarios | All asks derived from Steam Monthly Budget
A2: Steam launch only (M1–M12). Assumes no post-launch revenue at raise date. All totals live from Steam Monthly Budget sheet.
A4: LIVE MODEL TOTALS (update when Steam Assumptions change)
A5: Grand Total (Full Team) | B5: No Producer Total | C5: No Producer No Eng2 Total | D5: Lean Total (No Prod, No Eng2, Founder $3K)
A6: ='Steam Monthly Budget'!O42 -> 333250 | B6: ='Steam Monthly Budget'!O42-'Steam Monthly Budget'!O9 -> 279250 | C6: ='Steam Monthly Budget'!O42-'Steam Monthly Budget'!O9-'Steam Monthly Budget'!O7 -> 279250 | D6: ='Steam Monthly Budget'!O42-'Steam Monthly Budget'!O9-'Steam Monthly Budget'!O7-('Steam Assumptions'!B11-3000)*12 -> 267250
A8: FUNDING ASK — REVENUE OFFSET & BUFFER ASSUMPTIONS (edit BLUE cells)
A9: Scenario | B9: Steam Revenue Offset (post-M12) | C9: Buffer % | D9: Calculated Ask | E9: Base Total Used | F9: Derivation Note
A10: Absolute Floor — no Producer, no Eng2, Founder $3K | B10: 0 | C10: 0 | D10: =ROUND(('Steam Monthly Budget'!O42-'Steam Monthly Budget'!O9-'Steam Monthly Budget'!O7-('Steam Assumptions'!B11-3000)*12-B10)*(1+C10),-3) -> 267000 | E10: Lean Total (D6) | F10: Lean Total (no Producer, no Eng2, founder at $3K/mo) × (1+0%) − $0 offset. Minimum viable Steam-only raise.
A11: Lean Steam — no Producer, no Eng2 | B11: 0 | C11: 0 | D11: =ROUND(('Steam Monthly Budget'!O42-'Steam Monthly Budget'!O9-'Steam Monthly Budget'!O7-B11)*(1+C11),-3) -> 279000 | E11: No Prod / No Eng2 (C6) | F11: Grand Total minus Producer and Eng2 rows × (1+0%) − $0. Clean 3-person team (Founder+Eng1+Designer).
A12: Lean Steam + 10% buffer ★ RECOMMENDED FLOOR | B12: 0 | C12: 0.1 | D12: =ROUND(('Steam Monthly Budget'!O42-'Steam Monthly Budget'!O9-'Steam Monthly Budget'!O7-B12)*(1+C12),-3) -> 307000 | E12: No Prod / No Eng2 (C6) | F12: No Producer, no Eng2, Grand Total × 1.10. Modest buffer for scope/delay risk. Strong pre-seed posture.
A13: Base Steam — full team (incl. Producer, Eng2) | B13: 0 | C13: 0 | D13: =ROUND(('Steam Monthly Budget'!O42-B13)*(1+C13),-3) -> 333000 | E13: Grand Total (A6) | F13: Full Steam Grand Total × (1+0%) − $0. Includes all 5 roles, all conferences, contingency.
A14: Comfortable Steam — full team + 10% buffer | B14: 0 | C14: 0.1 | D14: =ROUND(('Steam Monthly Budget'!O42-B14)*(1+C14),-3) -> 367000 | E14: Grand Total (A6) | F14: Grand Total × 1.10 − $0. 10% buffer on full team. Balanced ask for investors.
A15: Conservative Steam — full team + 25% buffer | B15: 0 | C15: 0.25 | D15: =ROUND(('Steam Monthly Budget'!O42-B15)*(1+C15),-3) -> 417000 | E15: Grand Total (A6) | F15: Grand Total × 1.25 − $0. Maximum conservative Steam-only ask. Set this if you expect slow first months.
A17: ★ RECOMMENDED STEAM-ONLY ASK RANGE: $280K – $358K (Lean Steam floor to Lean Steam + 10% buffer). See rows 11–12 above — updates live. Excludes Producer, Eng2, and all mobile costs. If you add Producer or Eng2, the ask moves to the $303K–$380K range (rows 13–15).
A19: TEAM CONFIGURATION COMPARISON
A20: Scenario | B20: Ask Amount (live) | C20: Runway | D20: Team | E20: Key Trade-Off
A21: Absolute Floor (Founder $3K, no Prod, no Eng2) | B21: =TEXT(D10,"$#,##0") -> $267,000 | C21: 10–12 mo | D21: Founder + Eng1 + Designer | E21: Minimal viable team. High founder risk. No buffer at all.
A22: Lean Steam (Founder $4K, no Prod, no Eng2) | B22: =TEXT(D11,"$#,##0") -> $279,000 | C22: 12 mo | D22: Founder + Eng1 + Designer | E22: Cleanest 3-person team. No QA coverage. Founder bears all PM load.
A23: Lean + 10% buffer ★ | B23: =TEXT(D12,"$#,##0") -> $307,000 | C23: 12–13 mo | D23: Founder + Eng1 + Designer + buffer | E23: Best balance of lean and credible. Recommended pre-seed ask.
A24: Full Team, no buffer | B24: =TEXT(D13,"$#,##0") -> $333,000 | C24: 12 mo | D24: All 5 roles incl. Eng2 QA + Producer | E24: Full coverage, no padding. Requires all roles to stay on scope.
A25: Full Team + 10% buffer | B25: =TEXT(D14,"$#,##0") -> $367,000 | C25: 13 mo | D25: All 5 roles + buffer | E25: Solid full-team ask. Defensible for investors valuing process maturity.
A26: Full Team + 25% buffer | B26: =TEXT(D15,"$#,##0") -> $417,000 | C26: 14–15 mo | D26: All 5 roles + large buffer | E26: Maximum Steam-only ask. Strong if you expect slow ramp or scope risk.
A28: DE-RISKING FACTORS FOR INVESTOR PITCH (Steam-Only Framing)
A29: ✓ Working prototype exists | B29: Technical risk significantly lower than greenfield. Concept is validated.
A30: ✓ Simple port scope confirmed | B30: Unreal conversion = M1 only (pro-bono). Feature dev starts M2. Faster than typical.
A31: ✓ Steam-first focus | B31: Single platform reduces scope, QA cost, and cert overhead vs simultaneous mobile launch.
A32: ✓ Unreal Engine — free to $1M revenue | B32: Zero engine licensing cost until $1M gross revenue. Major cost advantage.
A33: ✓ Category white space on Steam | B33: 10 of 14 direct competitors have <200 reviews. Funded campaign leads immediately.
A34: ✓ Mobile optionality preserved | B34: Steam-only raise does not close the mobile door — it sequences it after revenue validation.
A35: ✓ 1099 contractor structure | B35: No payroll taxes, benefits, HR overhead. Clean, investor-friendly cost structure.
A36: ✓ Pro-bono Unreal engineering M1 | B36: Saves ~$8,500 vs. a paid M1. Signals team commitment to investors.
A38: ECHOSCAPE : Indie (Steam) Market Analysis | Budget Model v5 — Steam Only | April 2026 | Confidential
