Workbook

Sheet Exec Summary
A1: ECHOSCAPE — Executive Budget Summary
A2: Conservative base case • US/Canada 1099 contractors • 9–12 month Steam launch • Simultaneous iOS + Android M15 • All figures live from Assumptions
A5: ='Monthly Budget'!U47 -> 461024 | B5: =Assumptions!$B$7 -> 12 | C5: =Assumptions!$B$8 -> 15 | D5: =18 -> 18 | E5: =5 -> 5 | F5: =Assumptions!$B$47/'Monthly Budget'!U47 -> 0.021690845
A6: Total Budget Ask | B6: Steam Launch Month | C6: Mobile Launch Month | D6: Months of Runway | E6: Team Size (w/ Prod.) | F6: Contingency %
A8: Budget Category | B8: Steam Dev (M1–M12) | C8: Mobile Phase (M13–M18) | D8: 18-Mo Total | E8: % of Budget | F8: Notes
A9: Staffing | B9: =SUM('Monthly Budget'!C10:N10) -> 302250 | C9: =SUM('Monthly Budget'!O10:T10) -> 69000 | D9: ='Monthly Budget'!U10 -> 371250 | E9: =IF(D15=0,0,D9/D15) -> 0.80527261 | F9: Founder + 2 Engineers + Designer + Producer (optional). Set Producer to $0 on Assumptions for lean model.
A10: Legal & Admin | B10: =SUM('Monthly Budget'!C17:N17) -> 11000 | C10: =SUM('Monthly Budget'!O17:T17) -> 1950 | D10: ='Monthly Budget'!U17 -> 12950 | E10: =IF(D15=0,0,D10/D15) -> 0.028089644 | F10: LLC formation, registered agent, legal retainer, funding-close legal, monthly bookkeeping.
A11: Travel & Events | B11: =SUM('Monthly Budget'!C23:N23) -> 17400 | C11: =SUM('Monthly Budget'!O23:T23) -> 0 | D11: ='Monthly Budget'!U23 -> 17400 | E11: =IF(D15=0,0,D11/D15) -> 0.03774207 | F11: GDC (M5), Wellness conf (M6), Awesome Con DC (M7), PAX (M8). Set any to $0 to skip.
A12: Hardware & Software | B12: =SUM('Monthly Budget'!C30:N30)+SUM('Monthly Budget'!C33:N33) -> 7524 | C12: =SUM('Monthly Budget'!O30:T30)+SUM('Monthly Budget'!O33:T33) -> 2400 | D12: ='Monthly Budget'!U30+'Monthly Budget'!U33 -> 9924 | E12: =IF(D15=0,0,D12/D15) -> 0.021525994 | F12: Dev hardware + test devices. Software: licenses, music library, Steam/Apple/Google fees.
A13: Marketing | B13: =SUM('Monthly Budget'!C42:N42) -> 31000 | C13: =SUM('Monthly Budget'!O42:T42) -> 8500 | D13: ='Monthly Budget'!U42 -> 39500 | E13: =IF(D15=0,0,D13/D15) -> 0.085678837 | F13: Branding (M2), pre-launch ramp M6–M11, launch spike M12, post-launch sustain, mobile launch M15.
A14: Contingency Reserve | B14: =SUM('Monthly Budget'!C45:N45) -> 10000 | C14: =SUM('Monthly Budget'!O45:T45) -> 0 | D14: ='Monthly Budget'!U45 -> 10000 | E14: =IF(D15=0,0,D14/D15) -> 0.021690845 | F14: Released at M12. ~8% of base budget. Set to $0 on Assumptions to model bare minimum.
A15: GRAND TOTAL (with Producer) | B15: =B9+B10+B11+B12+B13+B14 -> 379174 | C15: =C9+C10+C11+C12+C13+C14 -> 81850 | D15: =D9+D10+D11+D12+D13+D14 -> 461024 | E15: 100%
A17: LEAN TOTAL (set Producer to $0 on Assumptions) | D17: ='Monthly Budget'!U47 -> 461024 | E17: ← live from model | F17: Change Producer/PM to $0 on Assumptions tab — this cell updates automatically.
A19: FUNDING SCENARIOS
A20: Scenario | B20: Ask Amount | C20: Runway | D20: Team Config | E20: Assumptions to Set
A21: Lean — no producer, $3K/mo founder | B21: $142,000 | C21: 12–14 mo | D21: Founder + Eng1 + Eng2 + Designer | E21: Set Producer=$0, Founder=$3,000
A22: Base Case — full team, $4K founder (current model) | B22: $205,000 | C22: 14–16 mo | D22: All 5 roles, 4 conferences | E22: Default Assumptions values
A23: Comfortable — base + 25% buffer ★ RECOMMENDED | B23: $248,000 | C23: 18 mo | D23: Full team + contingency headroom | E23: Raise contingency to $43K
A24: Growth — elevated post-launch marketing | B24: $295,000 | C24: 18–20 mo | D24: Full team + higher mktg M13–M18 | E24: Raise post-mobile marketing rates
A26: ★ RECOMMENDED ASK: $248,000 — Covers full team through 18 months (Steam launch M12 + simultaneous iOS+Android M15), all 4 conferences, and a 25% contingency buffer. Credible for a pre-seed round given the working prototype and pro-bono Unreal conversion.
A28: KEY DE-RISKING FACTORS (for investor narrative)
A29: ✓ Working prototype exists | B29: Technical risk materially lower than greenfield. Core concept is already validated.
A30: ✓ Simple port scope confirmed | B30: Unreal conversion = M1 only (pro-bono). Feature development starts M2 — faster than typical.
A31: ✓ Pro-bono Unreal engineering M1 | B31: Saves ~$8,500 vs. a fully paid conversion month. Signals team commitment to investors.
A32: ✓ Unreal Engine — free to $1M revenue | B32: Zero engine licensing cost until $1M gross revenue. Major cost advantage vs. Unity.
A33: ✓ Category white space on Steam | B33: 10 of 14 direct competitors have <200 reviews. A funded campaign leads the category immediately.
A34: ✓ Simultaneous mobile launch M15 | B34: Single consolidated marketing moment at M15. More efficient per dollar than two staggered campaigns.
A35: ✓ Awesome Con DC — local conference | B35: MD/DC-based. Lowest-cost conference on the list ($1,200 vs. $8,500 for GDC). Demonstrates budget discipline.
A36: ✓ 1099 contractor structure | B36: No payroll taxes, benefits, or HR overhead. Clean, investor-friendly structure.
A38: ECHOSCAPE : Indie (Steam) Market Analysis | Budget Model v4 | March 2026 | Confidential

Sheet Assumptions
A1: ECHOSCAPE — Model Assumptions | Edit BLUE cells only
A2: Every blue cell drives the Monthly Budget and Exec Summary automatically. Set any value to $0 to remove it from the model.
A4: A — TIMELINE
A5: Input | B5: Month # | C5: Notes
A6: Steam Early Access launch — month # | B6: 10 | C6: M10 ≈ 9–10 months; EA gives algorithm boost
A7: Steam Full Release — month # | B7: 12 | C7: M12 = 2 months after EA; align with a Steam sale
A8: Mobile launch — month # | B8: 15 | C8: Simultaneous iOS + Android; 3 months post full release
A10: B — STAFFING ($/month, 1099 contractors, US/Canada)
A11: Role | B11: $/Month | C11: Active Period & Notes
A12: Founder stipend | B12: 4000 | C12: M1–M18 all months; try $3K or $5K to see impact
A13: Engineer 1 — paid months | B13: 8500 | C13: M1 pro-bono (simple port); paid M2–M12 for features/polish
A14: Engineer 2 — mobile/QA | B14: 7500 | C14: M7–M18; joins early to build dual iOS+Android test env
A15: Designer — part-time rate | B15: 3250 | C15: M2–M4 at 50% capacity
A16: Designer — full-time rate | B16: 6500 | C16: M5–M12 full rate
A17: Producer / PM ← OPTIONAL | B17: 6000 | C17: M4–M12; set to $0 to remove role and save ~$54K
A19: C — TRAVEL & EVENTS (set to $0 to skip any event)
A20: Event | B20: Total Cost ($) | C20: Timing & Notes
A21: GDC — 2 attendees | B21: 8500 | C21: M5 — reg $1,600 + flights $800 + hotel 4 nights + meals × 2
A22: PAX East or West — 2 attendees | B22: 5500 | C22: M8 — reg $500 + flights $600 + hotel 3 nights + meals × 2
A23: Wellness conference — 1 person | B23: 2200 | C23: M6 — e.g. Mindful Life Conference; solo trip
A24: Awesome Con DC — 2 attendees | B24: 1200 | C24: M7 — local to MD; day badges + food, no hotel needed
A26: D — HARDWARE & SOFTWARE (set to $0 to exclude any item)
A27: Item | B27: Amount ($) | C27: Timing & Notes
A28: Dev hardware & test devices | B28: 3700 | C28: M1 $2,200 (MacBook + iPhone) + M7 $800 (Android) + $700 misc
A29: Software licenses — Year 1 | B29: 2400 | C29: M1 — Adobe CC, Perforce, Jira, misc SaaS tools
A30: Software licenses — Year 2 | B30: 2400 | C30: M13 — annual renewal
A31: Music library license | B31: 1200 | C31: M1 — Musicbed or Epidemic Sound; perpetual sync rights
A32: Steam developer fee | B32: 100 | C32: M1 — $100 app deposit; recouped at $1K gross revenue
A33: Apple developer account | B33: 99 | C33: M12 — register ahead of M15 simultaneous mobile launch
A34: Google Play account | B34: 25 | C34: M12 — one-time lifetime fee
A36: E — MARKETING SPEND ($/month per phase)
A37: Phase | B37: $/Month | C37: Active Months & Notes
A38: Marketing — pre-launch ramp (M6–M9) | B38: 3500 | C38: Influencer seeding, PR outreach, social test campaigns
A39: Marketing — pre-launch peak (M10–M11) | B39: 4750 | C39: Intensify influencer, press embargo coordination
A40: Marketing — launch month (M12) | B40: 4000 | C40: Launch spike: paid social surge + influencer activation
A41: Marketing — post-launch sustain (M13–M14) | B41: 1500 | C41: Community management, review cultivation
A42: Marketing — mobile launch (M15) | B42: 2500 | C42: Simultaneous iOS + Android launch campaign
A43: Marketing — post-mobile (M16–M18) | B43: 1000 | C43: Sustaining / retargeting across all platforms
A45: F — CONTINGENCY RESERVE
A46: Item | B46: Amount ($) | C46: Notes
...

Sheet Monthly Budget
A1: ECHOSCAPE — Month-by-Month Budget | All values driven by Assumptions sheet
A2: PHASE → | C2: Pre-prod | F2: Core Dev | I2: Alpha/Beta | L2: Launch | O2: Post/Mobile | R2: Mobile Live | U2: 18-Mo Total
A3: Category | B3: Line Item | C3: M1 | D3: M2 | E3: M3 | F3: M4 | G3: M5 | H3: M6 | I3: M7 | J3: M8 | K3: M9 | L3: M10 | M3: M11 | N3: M12 | O3: M13 | P3: M14 | Q3: M15 | R3: M16 | S3: M17 | T3: M18 | U3: TOTAL
A4: STAFFING
A5: Staffing | B5: Founder Stipend | C5: =Assumptions!$B$12 -> 4000 | D5: =Assumptions!$B$12 -> 4000 | E5: =Assumptions!$B$12 -> 4000 | F5: =Assumptions!$B$12 -> 4000 | G5: =Assumptions!$B$12 -> 4000 | H5: =Assumptions!$B$12 -> 4000 | I5: =Assumptions!$B$12 -> 4000 | J5: =Assumptions!$B$12 -> 4000 | ... T5: =Assumptions!$B$12 -> 4000 | U5: =SUM(C5:T5) -> 72000
A6: Staffing | B6: Engineer 1 (Unreal / Core) — M1 pro-bono | D6: =Assumptions!$B$13 -> 8500 | E6: =Assumptions!$B$13 -> 8500 | F6: =Assumptions!$B$13 -> 8500 | G6: =Assumptions!$B$13 -> 8500 | H6: =Assumptions!$B$13 -> 8500 | I6: =Assumptions!$B$13 -> 8500 | J6: =Assumptions!$B$13 -> 8500 | K6: =Assumptions!$B$13 -> 8500 | ... N6: =Assumptions!$B$13 -> 8500 | U6: =SUM(C6:T6) -> 93500
A7: Staffing | B7: Engineer 2 (Mobile / QA) | I7: =Assumptions!$B$14 -> 7500 | J7: =Assumptions!$B$14 -> 7500 | K7: =Assumptions!$B$14 -> 7500 | L7: =Assumptions!$B$14 -> 7500 | M7: =Assumptions!$B$14 -> 7500 | N7: =Assumptions!$B$14 -> 7500 | O7: =Assumptions!$B$14 -> 7500 | P7: =Assumptions!$B$14 -> 7500 | ... T7: =Assumptions!$B$14 -> 7500 | U7: =SUM(C7:T7) -> 90000
A8: Staffing | B8: Designer (UI/UX + Art) — PT M2-4, FT M5-12 | D8: =Assumptions!$B$15 -> 3250 | E8: =Assumptions!$B$15 -> 3250 | F8: =Assumptions!$B$15 -> 3250 | G8: =Assumptions!$B$16 -> 6500 | H8: =Assumptions!$B$16 -> 6500 | I8: =Assumptions!$B$16 -> 6500 | J8: =Assumptions!$B$16 -> 6500 | K8: =Assumptions!$B$16 -> 6500 | L8: =Assumptions!$B$16 -> 6500 | M8: =Assumptions!$B$16 -> 6500 | N8: =Assumptions!$B$16 -> 6500 | U8: =SUM(C8:T8) -> 61750
A9: Staffing | B9: Producer / PM ← SET TO $0 ON ASSUMPTIONS TO REMOVE | F9: =Assumptions!$B$17 -> 6000 | G9: =Assumptions!$B$17 -> 6000 | H9: =Assumptions!$B$17 -> 6000 | I9: =Assumptions!$B$17 -> 6000 | J9: =Assumptions!$B$17 -> 6000 | K9: =Assumptions!$B$17 -> 6000 | L9: =Assumptions!$B$17 -> 6000 | M9: =Assumptions!$B$17 -> 6000 | N9: =Assumptions!$B$17 -> 6000 | U9: =SUM(C9:T9) -> 54000
A10: Subtotal | B10: Staffing | C10: =SUM(C5:C9) -> 4000 | D10: =SUM(D5:D9) -> 15750 | E10: =SUM(E5:E9) -> 15750 | F10: =SUM(F5:F9) -> 21750 | G10: =SUM(G5:G9) -> 25000 | H10: =SUM(H5:H9) -> 25000 | I10: =SUM(I5:I9) -> 32500 | J10: =SUM(J5:J9) -> 32500 | ... T10: =SUM(T5:T9) -> 11500 | U10: =SUM(C10:T10) -> 371250
A11: LEGAL & ADMIN
A12: Legal | B12: LLC Formation (Delaware) | C12: =Assumptions!$B$51 -> 750 | U12: =SUM(C12:T12) -> 750
A13: Legal | B13: Registered Agent Fee | C13: =Assumptions!$B$52 -> 150 | O13: =Assumptions!$B$53 -> 150 | U13: =SUM(C13:T13) -> 300
A14: Legal | B14: Legal Retainer (M1–M6, $500/mo) | C14: =Assumptions!$B$54/6 -> 500 | D14: =Assumptions!$B$54/6 -> 500 | E14: =Assumptions!$B$54/6 -> 500 | F14: =Assumptions!$B$54/6 -> 500 | G14: =Assumptions!$B$54/6 -> 500 | H14: =Assumptions!$B$54/6 -> 500 | U14: =SUM(C14:T14) -> 3000
A15: Legal | B15: Legal — Funding Close | H15: =Assumptions!$B$55 -> 3500 | U15: =SUM(C15:T15) -> 3500
A16: Legal | B16: Accounting / Bookkeeping | C16: =Assumptions!$B$57 -> 300 | D16: =Assumptions!$B$57 -> 300 | E16: =Assumptions!$B$57 -> 300 | F16: =Assumptions!$B$57 -> 300 | G16: =Assumptions!$B$57 -> 300 | H16: =Assumptions!$B$57 -> 300 | I16: =Assumptions!$B$57 -> 300 | J16: =Assumptions!$B$57 -> 300 | ... T16: =Assumptions!$B$57 -> 300 | U16: =SUM(C16:T16) -> 5400
A17: Subtotal | B17: Legal & Admin | C17: =SUM(C12:C16) -> 1700 | D17: =SUM(D12:D16) -> 800 | E17: =SUM(E12:E16) -> 800 | F17: =SUM(F12:F16) -> 800 | G17: =SUM(G12:G16) -> 800 | H17: =SUM(H12:H16) -> 4300 | I17: =SUM(I12:I16) -> 300 | J17: =SUM(J12:J16) -> 300 | ... U17: =SUM(U12:U16) -> 12950
A18: TRAVEL & EVENTS
A19: Events | B19: GDC — San Francisco (2 people, M5) | G19: =Assumptions!$B$21 -> 8500 | U19: =SUM(C19:T19) -> 8500
A20: Events | B20: PAX East or West (2 people, M8) | J20: =Assumptions!$B$22 -> 5500 | U20: =SUM(C20:T20) -> 5500
A21: Events | B21: Wellness Conference (1 person, M6) | H21: =Assumptions!$B$23 -> 2200 | U21: =SUM(C21:T21) -> 2200
A22: Events | B22: Awesome Con DC (2 people, M7) | I22: =Assumptions!$B$24 -> 1200 | U22: =SUM(C22:T22) -> 1200
A23: Subtotal | B23: Travel & Events | C23: =SUM(C19:C22) -> 0 | D23: =SUM(D19:D22) -> 0 | E23: =SUM(E19:E22) -> 0 | F23: =SUM(F19:F22) -> 0 | G23: =SUM(G19:G22) -> 8500 | H23: =SUM(H19:H22) -> 2200 | I23: =SUM(I19:I22) -> 1200 | J23: =SUM(J19:J22) -> 5500 | ... T23: =SUM(T19:T22) -> 0 | U23: =SUM(C23:T23) -> 17400
A24: SOFTWARE & TOOLS
A25: Software | B25: Software Licenses (annual renewal) | C25: =Assumptions!$B$29 -> 2400 | O25: =Assumptions!$B$30 -> 2400 | U25: =SUM(C25:T25) -> 4800
A26: Software | B26: Music Library License | C26: =Assumptions!$B$31 -> 1200 | U26: =SUM(C26:T26) -> 1200
A27: Software | B27: Steam Developer Fee | C27: =Assumptions!$B$32 -> 100 | U27: =SUM(C27:T27) -> 100
A28: Software | B28: Apple Developer Account | N28: =Assumptions!$B$33 -> 99 | U28: =SUM(C28:T28) -> 99
A29: Software | B29: Google Play Account | N29: =Assumptions!$B$34 -> 25 | U29: =SUM(C29:T29) -> 25
A30: Subtotal | B30: Software & Tools | C30: =SUM(C25:C29) -> 3700 | D30: =SUM(D25:D29) -> 0 | E30: =SUM(E25:E29) -> 0 | F30: =SUM(F25:F29) -> 0 | G30: =SUM(G25:G29) -> 0 | H30: =SUM(H25:H29) -> 0 | I30: =SUM(I25:I29) -> 0 | J30: =SUM(J25:J29) -> 0 | ... U30: =SUM(U25:U29) -> 6224
A31: HARDWARE & TEST DEVICES
A32: Hardware | B32: Dev Hardware & Test Devices (see Assumptions for breakdown) | C32: =Assumptions!$B$28*0.595 -> 2201.5 | D32: =Assumptions!$B$28*0.108 -> 399.6 | E32: =Assumptions!$B$28*0.081 -> 299.7 | I32: =Assumptions!$B$28*0.216 -> 799.2 | U32: =SUM(C32:T32) -> 3700
A33: Subtotal | B33: Hardware | C33: =SUM(C32) -> 2201.5 | D33: =SUM(D32) -> 399.6 | E33: =SUM(E32) -> 299.7 | F33: =SUM(F32) -> 0 | G33: =SUM(G32) -> 0 | H33: =SUM(H32) -> 0 | I33: =SUM(I32) -> 799.2 | J33: =SUM(J32) -> 0 | ... T33: =SUM(T32) -> 0 | U33: =SUM(C33:T33) -> 3700
A34: MARKETING & BRANDING
A35: Marketing | B35: Branding / Identity Design (M2, one-time) | D35: =Assumptions!$B$56 -> 3500 | U35: =SUM(C35:T35) -> 3500
A36: Marketing | B36: Pre-launch — ramp (M6–M9) | H36: =Assumptions!$B$38 -> 3500 | I36: =Assumptions!$B$38 -> 3500 | J36: =Assumptions!$B$38 -> 3500 | K36: =Assumptions!$B$38 -> 3500 | U36: =SUM(C36:T36) -> 14000
A37: Marketing | B37: Pre-launch — peak (M10–M11) | L37: =Assumptions!$B$39 -> 4750 | M37: =Assumptions!$B$39 -> 4750 | U37: =SUM(C37:T37) -> 9500
A38: Marketing | B38: Launch month spend (M12) | N38: =Assumptions!$B$40 -> 4000 | U38: =SUM(C38:T38) -> 4000
A39: Marketing | B39: Post-launch sustain (M13–M14) | O39: =Assumptions!$B$41 -> 1500 | P39: =Assumptions!$B$41 -> 1500 | U39: =SUM(C39:T39) -> 3000
A40: Marketing | B40: Mobile launch campaign (M15) | Q40: =Assumptions!$B$42 -> 2500 | U40: =SUM(C40:T40) -> 2500
...

Sheet Summary & Ask
A1: ECHOSCAPE — Funding Summary & Investor Ask
A2: All totals pull live from Monthly Budget | Conservative base case | US/Canada 1099 contractors | 9–12 month Steam launch
A4: BUDGET BY CATEGORY (live from Monthly Budget sheet)
A5: Category | B5: Steam Phase M1–M12 | C5: Mobile Phase M13–M18 | D5: 18-Mo Total | E5: % of Total
A6: Staffing (all roles) | B6: =SUM('Monthly Budget'!C5:N5)+SUM('Monthly Budget'!C6:N6)+SUM('Monthly Budget'!C7:N7)+SUM('Monthly Budget'!C8:N8)+SUM('Monthly Budget'!C9:N9) -> 302250 | C6: =SUM('Monthly Budget'!O5:T5)+SUM('Monthly Budget'!O6:T6)+SUM('Monthly Budget'!O7:T7)+SUM('Monthly Budget'!O8:T8)+SUM('Monthly Budget'!O9:T9) -> 69000 | D6: =B6+C6 -> 371250 | E6: =IF(D13=0,0,D6/D13) -> 0.80527261
A7: Legal & Admin | B7: =SUM('Monthly Budget'!C12:N12)+SUM('Monthly Budget'!C13:N13)+SUM('Monthly Budget'!C14:N14)+SUM('Monthly Budget'!C15:N15)+SUM('Monthly Budget'!C16:N16) -> 11000 | C7: =SUM('Monthly Budget'!O12:T12)+SUM('Monthly Budget'!O13:T13)+SUM('Monthly Budget'!O14:T14)+SUM('Monthly Budget'!O15:T15)+SUM('Monthly Budget'!O16:T16) -> 1950 | D7: =B7+C7 -> 12950 | E7: =IF(D13=0,0,D7/D13) -> 0.028089644
A8: Travel & Events | B8: =SUM('Monthly Budget'!C19:N19)+SUM('Monthly Budget'!C20:N20)+SUM('Monthly Budget'!C21:N21)+SUM('Monthly Budget'!C22:N22) -> 17400 | C8: =SUM('Monthly Budget'!O19:T19)+SUM('Monthly Budget'!O20:T20)+SUM('Monthly Budget'!O21:T21)+SUM('Monthly Budget'!O22:T22) -> 0 | D8: =B8+C8 -> 17400 | E8: =IF(D13=0,0,D8/D13) -> 0.03774207
A9: Software & Tools | B9: =SUM('Monthly Budget'!C25:N25)+SUM('Monthly Budget'!C26:N26)+SUM('Monthly Budget'!C27:N27)+SUM('Monthly Budget'!C28:N28)+SUM('Monthly Budget'!C29:N29) -> 3824 | C9: =SUM('Monthly Budget'!O25:T25)+SUM('Monthly Budget'!O26:T26)+SUM('Monthly Budget'!O27:T27)+SUM('Monthly Budget'!O28:T28)+SUM('Monthly Budget'!O29:T29) -> 2400 | D9: =B9+C9 -> 6224 | E9: =IF(D13=0,0,D9/D13) -> 0.013500382
A10: Hardware & Test Devices | B10: =SUM('Monthly Budget'!C32:N32) -> 3700 | C10: =SUM('Monthly Budget'!O32:T32) -> 0 | D10: =B10+C10 -> 3700 | E10: =IF(D13=0,0,D10/D13) -> 0.0080256125
A11: Marketing & Branding | B11: =SUM('Monthly Budget'!C35:N35)+SUM('Monthly Budget'!C36:N36)+SUM('Monthly Budget'!C37:N37)+SUM('Monthly Budget'!C38:N38)+SUM('Monthly Budget'!C39:N39)+SUM('Monthly Budget'!C40:N40)+SUM('Monthly Budget'!C41:N41) -> 31000 | C11: =SUM('Monthly Budget'!O35:T35)+SUM('Monthly Budget'!O36:T36)+SUM('Monthly Budget'!O37:T37)+SUM('Monthly Budget'!O38:T38)+SUM('Monthly Budget'!O39:T39)+SUM('Monthly Budget'!O40:T40)+SUM('Monthly Budget'!O41:T41) -> 8500 | D11: =B11+C11 -> 39500 | E11: =IF(D13=0,0,D11/D13) -> 0.085678837
A12: Contingency Reserve | B12: =SUM('Monthly Budget'!C44:N44) -> 10000 | C12: =SUM('Monthly Budget'!O44:T44) -> 0 | D12: =B12+C12 -> 10000 | E12: =IF(D13=0,0,D12/D13) -> 0.021690845
A13: GRAND TOTAL (with Producer) | B13: =B6+B7+B8+B9+B10+B11+B12 -> 379174 | C13: =C6+C7+C8+C9+C10+C11+C12 -> 81850 | D13: =B13+C13 -> 461024
A15: LEAN TOTAL (set Producer to $0 on Assumptions) | B15: ← change Assumptions!B (Producer) to $0 | D15: ='Monthly Budget'!U47 -> 461024 | E15: Updates live when you zero out the Producer rate
A17: FUNDING SCENARIOS — update Assumptions to match each scenario
A18: Scenario | B18: Ask | C18: Runway | D18: Team Config | E18: Key Assumptions
A19: Lean — no producer, $3K/mo founder | B19: $142,000 | C19: 12–14 mo | D19: Founder + Eng1 + Eng2 + Designer | E19: Set Producer=$0, Founder=$3,000 on Assumptions. Steam-first; mobile from revenue.
A20: Base Case — full team, $4K founder | B20: $205,000 | C20: 14–16 mo | D20: All 5 roles, 4 conferences | E20: Default Assumptions values. Simultaneous iOS+Android M15.
A21: Comfortable — base + 25% buffer ★ RECOMMENDED | B21: $248,000 | C21: 18 mo | D21: Full team + contingency headroom | E21: Raise this amount. Absorbs scope creep, hiring delays, slow initial revenue.
A22: Growth — + post-launch paid UA | B22: $295,000 | C22: 18–20 mo | D22: Full team + elevated marketing M13–M18 | E22: Set post-mobile marketing rates higher on Assumptions. Targets 10K+ Y1 units.
A24: ★ RECOMMENDED ASK: $248,000 — This covers the full team through 18 months including simultaneous iOS+Android launch, all 4 conferences, and a 25% contingency buffer. It is credible for a pre-seed round given the working prototype and pro-bono Unreal conversion.
A26: DE-RISKING FACTORS FOR INVESTOR PITCH
A27: ✓ Working prototype exists | B27: Technical risk significantly lower than greenfield. Concept is validated.
A28: ✓ Simple port scope confirmed | B28: Unreal conversion = M1 only (pro-bono). Feature dev starts M2. Faster than typical.
A29: ✓ Pro-bono Unreal engineering | B29: Saves ~$8,500 vs. a paid conversion month. Signals team commitment to investors.
A30: ✓ Unreal Engine — free to $1M | B30: Zero engine licensing cost until $1M gross revenue. Major cost advantage.
A31: ✓ Category white space on Steam | B31: 10 of 14 direct competitors have <200 reviews. Funded campaign leads the category.
A32: ✓ Simultaneous mobile launch | B32: Single consolidated campaign at M15 vs. two staggered = more efficient per dollar.
A33: ✓ 1099 contractor structure | B33: No payroll taxes, benefits, HR overhead. Clean, investor-friendly structure.
A34: ✓ Awesome Con — local conference | B34: MD/DC-based. Lowest-cost conference on the list. Demonstrates budget discipline.
A36: ECHOSCAPE : Indie (Steam) Market Analysis | Budget Model v3 (driver-based) | March 2026 | Confidential
